<?xml version="1.0"?>
<robot name="wheel" xmlns:xacro="http://ros.org/wiki/xacro">

  <xacro:property name="tango_wheel_mesh" value="package://tango_description/meshes/visual_model/tango_wheel.dae"/>
    
  <xacro:macro name="wheel_inertial" params="mass">
    <inertial>
      <mass value="${mass}"/>
      <inertia ixx="0.0028656" ixy="-0.0000000" ixz="0.0000000" iyy="0.0028655" iyz="-0.0000000" izz="0.0055831" />
    </inertial>
  </xacro:macro>
  
  <xacro:macro name="wheel" params="prefix parent link_xyz link_rpy joint_xyz joint_rpy radius height mass">
    <link name="${prefix}_wheel_link">
      <visual>
        <origin xyz="${link_xyz}" rpy="${link_rpy}" />
        <geometry>
	   <mesh filename="${tango_wheel_mesh}"/>
        </geometry>
        <material name="black"/>
      </visual>
      
      <collision>
        <origin xyz="${link_xyz}" rpy="${link_rpy}" />
        <geometry>
          <cylinder radius="${radius}" length="${height}"/>
        </geometry>
      </collision>
      <xacro:wheel_inertial mass="${mass}"/>
    </link>
    
    <joint name="${prefix}_wheel_joint" type="continuous">
      <parent link="${parent}"/>
      <child link="${prefix}_wheel_link"/>
      <origin xyz="${joint_xyz}" rpy="${joint_rpy}"/>
      <axis xyz="0 1 0"/>
      <joint_properties damping="0.0" friction="0.0"/>
    </joint>
    
    <gazebo reference="${prefix}_wheel_link">
      <kp>1000000.0</kp>
      <kd>1.0</kd>
      <mu1>0.8</mu1>
      <mu2>0.8</mu2>
      <maxVel>0.0</maxVel>
      <minDepth>0.001</minDepth>
      <turnGravityOff>false</turnGravityOff>
    </gazebo>
    
    <transmission name="${prefix}_trans">
      <type>transmission_interface/SimpleTransmission</type>
      <joint name="${prefix}_wheel_joint">
        <hardwareInterface>hardware_interface/EffortJointInterface</hardwareInterface>
      </joint>
      <actuator name="${prefix}_motor">
        <hardwareInterface>hardware_interface/EffortJointInterface</hardwareInterface>
        <mechanicalReduction>10</mechanicalReduction>
      </actuator>
    </transmission>
  </xacro:macro>

</robot>
